<robot name="my_robot">
    <link name="link1" />  
    <link name="link2">
        <visual>
            <origin xyz=".5 0 0" rpy="0 1.57 0" />
            <geometry>
                <cylinder radius=".05" length="1"/>
            </geometry>
            <material name="yellow">
                <color rgba="0.8 0.8 0 1"/>
            </material>
        </visual>
    </link>       
    <link name="link3">
        <visual>
            <origin xyz=".5 0 0" rpy="0 1.57 0" />
            <geometry>
                <cylinder radius=".05" length="1"/>
            </geometry>
            <material name="red">
                <color rgba="1 0 0 1"/>
            </material>
        </visual>
    </link>   
    <link name="link4">
    </link>
    <joint name="joint1" type="continuous">
        <parent link="link1"/>
        <child link="link2"/>
        <origin xyz="0 0 0" rpy="0 0 0" />
        <axis xyz="0 0 1" />
    </joint>
    
    <joint name="joint2" type="continuous">
        <parent link="link2"/>
        <child link="link3" />
        <origin xyz="1 0 0" rpy="0 0 0" />
        <axis xyz="0 0 1" />
    </joint>
    <joint name="joint3" type="continuous">
        <parent link="link3"/>
        <child link="link4" />
        <origin xyz="1 0 0" rpy="0 0 0" />
        <axis xyz="0 0 1" />
    </joint>
    
</robot>
